Workbook

Sheet Summary Data
A1: Condition | B1: Measured | D1: Sampled with ADC
B2: Average | C2: Standard Deviation | D2: Average | E2: Standard Deviation
A3: Completely Dry | B3: =AVERAGE('Manual Data'!B2:D2) -> 3.2933333 | C3: =STDEV('Manual Data'!B2:D2) -> 0.00057735027 | D3: 3.3 | E3: 0
A4: Blowing on it | B4: ='Manual Data'!B3:D3 -> 3.293 | C4: =STDEV('Manual Data'!B3:D3) -> 0.10319561 | D4: =AVERAGE('Automated Data'!C15:C24) -> 2.3893571 | E4: =STDEV('Automated Data'!C15:C24) -> 0.5383107
A5: Half wiped down with the Wet Wipe | B5: =AVERAGE('Manual Data'!B4:D4) -> 2.228 | C5: =STDEV('Manual Data'!B4:D4) -> 0.61774105 | D5: =AVERAGE('Automated Data'!C28:C37) -> 1.6869 | E5: =STDEV('Automated Data'!C28:C37) -> 0.54764677
A6: Entire Surface Wiped | B6: =AVERAGE('Manual Data'!B5:D5) -> 1.238 | C6: =STDEV('Manual Data'!B5:D5) -> 0.42292316 | D6: =AVERAGE('Automated Data'!C41:C50) -> 0.9095 | E6: =STDEV('Automated Data'!C41:C50) -> 0.19991568
A7: Wipe on Entire Surface | B7: =AVERAGE('Manual Data'!B6:D6) -> 0.9854 | C7: =STDEV('Manual Data'!B6:D6) -> 0.38738389 | D7: =AVERAGE('Automated Data'!C54:C63) -> 0.469 | E7: =STDEV('Automated Data'!C54:C63) -> 0.014047538

Sheet Manual Data
A1: Condition | B1: Sample 1 (V) | C1: Sample 2 (V) | D1: Sample 3 (V)
A2: Completely Dry | B2: 3.294 | C2: 3.293 | D2: 3.293
A3: Blowing on it | B3: 3.293 | C3: 3.179 | D3: 3.087
A4: Half Wiped | B4: 2.75 | C4: 2.388 | D4: 1.546
A5: Fully wiped | B5: 1.61 | C5: 1.326 | D5: 0.778
A6: Wipe stay on surface | B6: 1.416 | C6: 0.875 | D6: 0.6652

Sheet Automated Data
A1: Time (s) | B1: ADC | C1: Voltage (V)
A2: Dry
A3: 1090 | B3: 4095 | C3: 3.3
A4: 2190 | B4: 4095 | C4: 3.3
A5: 3290 | B5: 4095 | C5: 3.3
A6: 4390 | B6: 4095 | C6: 3.3
A7: 5490 | B7: 4095 | C7: 3.3
A8: 6590 | B8: 4095 | C8: 3.3
A9: 7690 | B9: 4095 | C9: 3.3
A10: 8790 | B10: 4095 | C10: 3.3
A11: 9890 | B11: 4095 | C11: 3.3
C12: =AVERAGE(C3:C11) -> 3.3 | D12: Average
A14: Blowing
A15: 1 | B15: 2089 | C15: 1.683
A16: 1090 | B16: 2079 | C16: 1.675
A17: 2190 | B17: 2390 | C17: 1.926
A18: 3290 | B18: 2791 | C18: 2.249
A19: 4390 | B19: 3511 | C19: 2.829
A20: 5490 | B20: 2543 | C20: 2.049
A21: 6600 | B21: 2255 | C21: 2.63
A22: 7700 | B22: 2251 | C22: 2.7904286
A23: 8800 | B23: 2416 | C23: 2.9508571
A24: 9910 | B24: 2293 | C24: 3.1112857
C25: =AVERAGE(C15:C24) -> 2.3893571 | D25: Average
A27: Half Wiped
A28: 0 | B28: 2911 | C28: 2.346
A29: 1100 | B29: 751 | C29: 0.605
A30: 2200 | B30: 1568 | C30: 1.264
A31: 3300 | B31: 1721 | C31: 1.387
A32: 4400 | B32: 1828 | C32: 1.473
A33: 5500 | B33: 1957 | C33: 1.577
A34: 6600 | B34: 2149 | C34: 1.732
A35: 7700 | B35: 2419 | C35: 1.949
A36: 8800 | B36: 2685 | C36: 2.164
A37: 9900 | B37: 2943 | C37: 2.372
C38: =AVERAGE(C28:C37) -> 1.6869 | D38: Average
A40: Full Wiped
A41: 0 | B41: 511 | C41: 0.412
A42: 1100 | B42: 1011 | C42: 0.815
A43: 2200 | B43: 1096 | C43: 0.883
...
